[2025-07-06 14:32:32,442: INFO: main: >>>>>> Stage: Data Ingestion stage started <<<<<<]
[2025-07-06 14:32:32,443: INFO: common: yaml file: config\config.yaml loaded successfully]
[2025-07-06 14:32:32,444: ERROR: main: yaml file is empty]
Traceback (most recent call last):
  File "C:\Users\Ayaz Khan\Desktop\Chest-Cancer-Classification\src\cnnClassifier\utils\common.py", line 32, in read_yaml
    return ConfigBox(content)
           ^^^^^^^^^^^^^^^^^^
  File "box\\box.py", line 295, in box.box.Box.__init__
box.exceptions.BoxValueError: First argument must be mapping or iterable

During handling of the above exception, another exception occurred:

Traceback (most recent call last):
  File "C:\Users\Ayaz Khan\Desktop\Chest-Cancer-Classification\main.py", line 18, in <module>
    data_ingestion.main()
  File "C:\Users\Ayaz Khan\Desktop\Chest-Cancer-Classification\src\cnnClassifier\pipeline\stage_01_data_ingestion.py", line 12, in main
    config = ConfigurationManager()
             ^^^^^^^^^^^^^^^^^^^^^^
  File "C:\Users\Ayaz Khan\Desktop\Chest-Cancer-Classification\src\cnnClassifier\config\configuration.py", line 15, in __init__
    self.config = read_yaml(config_filepath)
                  ^^^^^^^^^^^^^^^^^^^^^^^^^^
  File "C:\Users\Ayaz Khan\Desktop\Chest-Cancer-Classification\.venv\Lib\site-packages\ensure\main.py", line 872, in __call__
    return_val = self.f(*args, **kwargs)
                 ^^^^^^^^^^^^^^^^^^^^^^^
  File "C:\Users\Ayaz Khan\Desktop\Chest-Cancer-Classification\src\cnnClassifier\utils\common.py", line 34, in read_yaml
    raise ValueError("yaml file is empty")
ValueError: yaml file is empty
[2025-07-06 14:33:27,097: INFO: main: >>>>>> Stage: Data Ingestion stage started <<<<<<]
[2025-07-06 14:33:27,098: INFO: common: yaml file: config\config.yaml loaded successfully]
[2025-07-06 14:33:27,098: ERROR: main: yaml file is empty]
Traceback (most recent call last):
  File "C:\Users\Ayaz Khan\Desktop\Chest-Cancer-Classification\src\cnnClassifier\utils\common.py", line 32, in read_yaml
    return ConfigBox(content)
           ^^^^^^^^^^^^^^^^^^
  File "box\\box.py", line 295, in box.box.Box.__init__
box.exceptions.BoxValueError: First argument must be mapping or iterable

During handling of the above exception, another exception occurred:

Traceback (most recent call last):
  File "C:\Users\Ayaz Khan\Desktop\Chest-Cancer-Classification\main.py", line 18, in <module>
    data_ingestion.main()
  File "C:\Users\Ayaz Khan\Desktop\Chest-Cancer-Classification\src\cnnClassifier\pipeline\stage_01_data_ingestion.py", line 12, in main
    config = ConfigurationManager()
             ^^^^^^^^^^^^^^^^^^^^^^
  File "C:\Users\Ayaz Khan\Desktop\Chest-Cancer-Classification\src\cnnClassifier\config\configuration.py", line 15, in __init__
    self.config = read_yaml(config_filepath)
                  ^^^^^^^^^^^^^^^^^^^^^^^^^^
  File "C:\Users\Ayaz Khan\Desktop\Chest-Cancer-Classification\.venv\Lib\site-packages\ensure\main.py", line 872, in __call__
    return_val = self.f(*args, **kwargs)
                 ^^^^^^^^^^^^^^^^^^^^^^^
  File "C:\Users\Ayaz Khan\Desktop\Chest-Cancer-Classification\src\cnnClassifier\utils\common.py", line 34, in read_yaml
    raise ValueError("yaml file is empty")
ValueError: yaml file is empty
[2025-07-06 14:34:49,615: INFO: main: >>>>>> Stage: Data Ingestion stage started <<<<<<]
[2025-07-06 14:34:49,617: INFO: common: yaml file: config\config.yaml loaded successfully]
[2025-07-06 14:34:49,617: ERROR: main: yaml file is empty]
Traceback (most recent call last):
  File "C:\Users\Ayaz Khan\Desktop\Chest-Cancer-Classification\src\cnnClassifier\utils\common.py", line 32, in read_yaml
    return ConfigBox(content)
           ^^^^^^^^^^^^^^^^^^
  File "box\\box.py", line 295, in box.box.Box.__init__
box.exceptions.BoxValueError: First argument must be mapping or iterable

During handling of the above exception, another exception occurred:

Traceback (most recent call last):
  File "C:\Users\Ayaz Khan\Desktop\Chest-Cancer-Classification\main.py", line 18, in <module>
    data_ingestion.main()
  File "C:\Users\Ayaz Khan\Desktop\Chest-Cancer-Classification\src\cnnClassifier\pipeline\stage_01_data_ingestion.py", line 12, in main
    config = ConfigurationManager()
             ^^^^^^^^^^^^^^^^^^^^^^
  File "C:\Users\Ayaz Khan\Desktop\Chest-Cancer-Classification\src\cnnClassifier\config\configuration.py", line 15, in __init__
    self.config = read_yaml(config_filepath)
                  ^^^^^^^^^^^^^^^^^^^^^^^^^^
  File "C:\Users\Ayaz Khan\Desktop\Chest-Cancer-Classification\.venv\Lib\site-packages\ensure\main.py", line 872, in __call__
    return_val = self.f(*args, **kwargs)
                 ^^^^^^^^^^^^^^^^^^^^^^^
  File "C:\Users\Ayaz Khan\Desktop\Chest-Cancer-Classification\src\cnnClassifier\utils\common.py", line 34, in read_yaml
    raise ValueError("yaml file is empty")
ValueError: yaml file is empty
[2025-07-06 14:36:37,964: INFO: main: >>>>>> Stage: Data Ingestion stage started <<<<<<]
[2025-07-06 14:36:37,964: INFO: common: yaml file: config\config.yaml loaded successfully]
[2025-07-06 14:36:37,964: ERROR: main: yaml file is empty]
Traceback (most recent call last):
  File "C:\Users\Ayaz Khan\Desktop\Chest-Cancer-Classification\src\cnnClassifier\utils\common.py", line 32, in read_yaml
    return ConfigBox(content)
           ^^^^^^^^^^^^^^^^^^
  File "box\\box.py", line 295, in box.box.Box.__init__
box.exceptions.BoxValueError: First argument must be mapping or iterable

During handling of the above exception, another exception occurred:

Traceback (most recent call last):
  File "C:\Users\Ayaz Khan\Desktop\Chest-Cancer-Classification\main.py", line 18, in <module>
    data_ingestion.main()
  File "C:\Users\Ayaz Khan\Desktop\Chest-Cancer-Classification\src\cnnClassifier\pipeline\stage_01_data_ingestion.py", line 12, in main
    config = ConfigurationManager()
             ^^^^^^^^^^^^^^^^^^^^^^
  File "C:\Users\Ayaz Khan\Desktop\Chest-Cancer-Classification\src\cnnClassifier\config\configuration.py", line 15, in __init__
    self.config = read_yaml(config_filepath)
                  ^^^^^^^^^^^^^^^^^^^^^^^^^^
  File "C:\Users\Ayaz Khan\Desktop\Chest-Cancer-Classification\.venv\Lib\site-packages\ensure\main.py", line 872, in __call__
    return_val = self.f(*args, **kwargs)
                 ^^^^^^^^^^^^^^^^^^^^^^^
  File "C:\Users\Ayaz Khan\Desktop\Chest-Cancer-Classification\src\cnnClassifier\utils\common.py", line 34, in read_yaml
    raise ValueError("yaml file is empty")
ValueError: yaml file is empty
[2025-07-06 14:37:07,060: INFO: main: >>>>>> Stage: Data Ingestion stage started <<<<<<]
[2025-07-06 14:37:07,060: INFO: common: yaml file: config\config.yaml loaded successfully]
[2025-07-06 14:37:07,060: ERROR: main: yaml file is empty]
Traceback (most recent call last):
  File "C:\Users\Ayaz Khan\Desktop\Chest-Cancer-Classification\src\cnnClassifier\utils\common.py", line 32, in read_yaml
    return ConfigBox(content)
           ^^^^^^^^^^^^^^^^^^
  File "box\\box.py", line 295, in box.box.Box.__init__
box.exceptions.BoxValueError: First argument must be mapping or iterable

During handling of the above exception, another exception occurred:

Traceback (most recent call last):
  File "C:\Users\Ayaz Khan\Desktop\Chest-Cancer-Classification\main.py", line 18, in <module>
    data_ingestion.main()
  File "C:\Users\Ayaz Khan\Desktop\Chest-Cancer-Classification\src\cnnClassifier\pipeline\stage_01_data_ingestion.py", line 12, in main
    config = ConfigurationManager()
             ^^^^^^^^^^^^^^^^^^^^^^
  File "C:\Users\Ayaz Khan\Desktop\Chest-Cancer-Classification\src\cnnClassifier\config\configuration.py", line 15, in __init__
    self.config = read_yaml(config_filepath)
                  ^^^^^^^^^^^^^^^^^^^^^^^^^^
  File "C:\Users\Ayaz Khan\Desktop\Chest-Cancer-Classification\.venv\Lib\site-packages\ensure\main.py", line 872, in __call__
    return_val = self.f(*args, **kwargs)
                 ^^^^^^^^^^^^^^^^^^^^^^^
  File "C:\Users\Ayaz Khan\Desktop\Chest-Cancer-Classification\src\cnnClassifier\utils\common.py", line 34, in read_yaml
    raise ValueError("yaml file is empty")
ValueError: yaml file is empty
[2025-07-06 14:40:07,169: INFO: main: >>>>>> Stage: Data Ingestion stage started <<<<<<]
[2025-07-06 14:40:07,169: INFO: common: yaml file: config\config.yaml loaded successfully]
[2025-07-06 14:40:07,169: ERROR: main: yaml file is empty]
Traceback (most recent call last):
  File "C:\Users\Ayaz Khan\Desktop\Chest-Cancer-Classification\src\cnnClassifier\utils\common.py", line 32, in read_yaml
    return ConfigBox(content)
           ^^^^^^^^^^^^^^^^^^
  File "box\\box.py", line 295, in box.box.Box.__init__
box.exceptions.BoxValueError: First argument must be mapping or iterable

During handling of the above exception, another exception occurred:

Traceback (most recent call last):
  File "C:\Users\Ayaz Khan\Desktop\Chest-Cancer-Classification\main.py", line 18, in <module>
    data_ingestion.main()
  File "C:\Users\Ayaz Khan\Desktop\Chest-Cancer-Classification\src\cnnClassifier\pipeline\stage_01_data_ingestion.py", line 12, in main
    config = ConfigurationManager()
             ^^^^^^^^^^^^^^^^^^^^^^
  File "C:\Users\Ayaz Khan\Desktop\Chest-Cancer-Classification\src\cnnClassifier\config\configuration.py", line 15, in __init__
    self.config = read_yaml(config_filepath)
                  ^^^^^^^^^^^^^^^^^^^^^^^^^^
  File "C:\Users\Ayaz Khan\Desktop\Chest-Cancer-Classification\.venv\Lib\site-packages\ensure\main.py", line 872, in __call__
    return_val = self.f(*args, **kwargs)
                 ^^^^^^^^^^^^^^^^^^^^^^^
  File "C:\Users\Ayaz Khan\Desktop\Chest-Cancer-Classification\src\cnnClassifier\utils\common.py", line 34, in read_yaml
    raise ValueError("yaml file is empty")
ValueError: yaml file is empty
[2025-07-06 14:42:01,669: INFO: main: >>>>>> Stage: Data Ingestion stage started <<<<<<]
[2025-07-06 14:42:01,686: INFO: common: yaml file: config\config.yaml loaded successfully]
[2025-07-06 14:42:01,686: INFO: common: yaml file: params.yaml loaded successfully]
[2025-07-06 14:42:01,686: INFO: common: created directory at: artifacts]
[2025-07-06 14:42:01,686: INFO: common: created directory at: artifacts/data_ingestion]
[2025-07-06 14:42:01,686: INFO: data_ingestion: Downloading data from https://drive.google.com/file/d/1z0mreUtRmR-P-magILsDR3T7M6IkGXtY/view?usp=sharing into file artifacts/data_ingestion/data.zip]
[2025-07-06 14:42:26,290: INFO: data_ingestion: Downloaded data from https://drive.google.com/file/d/1z0mreUtRmR-P-magILsDR3T7M6IkGXtY/view?usp=sharing into file artifacts/data_ingestion/data.zip]
[2025-07-06 14:42:26,816: INFO: main: >>>>>> Stage: Data Ingestion stage completed <<<<<<

x==========x]
[2025-07-06 14:42:26,816: INFO: main: >>>>>> Stage: Prepare base model started <<<<<<]
[2025-07-06 14:42:26,816: INFO: common: yaml file: config\config.yaml loaded successfully]
[2025-07-06 14:42:26,816: INFO: common: yaml file: params.yaml loaded successfully]
[2025-07-06 14:42:26,816: INFO: common: created directory at: artifacts]
[2025-07-06 14:42:26,816: INFO: common: created directory at: artifacts/prepare_base_model]
[2025-07-06 14:42:26,816: ERROR: main: `input_shape` must be a tuple of three integers.]
Traceback (most recent call last):
  File "C:\Users\Ayaz Khan\Desktop\Chest-Cancer-Classification\main.py", line 29, in <module>
    prepare_base_model.main()
  File "C:\Users\Ayaz Khan\Desktop\Chest-Cancer-Classification\src\cnnClassifier\pipeline\stage_02_prepare_base_model.py", line 19, in main
    prepare_base_model.get_base_model()
  File "C:\Users\Ayaz Khan\Desktop\Chest-Cancer-Classification\src\cnnClassifier\components\prepare_base_model.py", line 14, in get_base_model
    self.model = tf.keras.applications.vgg16.VGG16(
                 ^^^^^^^^^^^^^^^^^^^^^^^^^^^^^^^^^^
  File "C:\Users\Ayaz Khan\Desktop\Chest-Cancer-Classification\.venv\Lib\site-packages\keras\src\applications\vgg16.py", line 112, in VGG16
    input_shape = imagenet_utils.obtain_input_shape(
                  ^^^^^^^^^^^^^^^^^^^^^^^^^^^^^^^^^^
  File "C:\Users\Ayaz Khan\Desktop\Chest-Cancer-Classification\.venv\Lib\site-packages\keras\src\applications\imagenet_utils.py", line 379, in obtain_input_shape
    raise ValueError(
ValueError: `input_shape` must be a tuple of three integers.
[2025-07-06 14:43:06,782: INFO: main: >>>>>> Stage: Data Ingestion stage started <<<<<<]
[2025-07-06 14:43:06,782: INFO: common: yaml file: config\config.yaml loaded successfully]
[2025-07-06 14:43:06,784: INFO: common: yaml file: params.yaml loaded successfully]
[2025-07-06 14:43:06,784: INFO: common: created directory at: artifacts]
[2025-07-06 14:43:06,784: INFO: common: created directory at: artifacts/data_ingestion]
[2025-07-06 14:43:06,784: INFO: data_ingestion: Downloading data from https://drive.google.com/file/d/1z0mreUtRmR-P-magILsDR3T7M6IkGXtY/view?usp=sharing into file artifacts/data_ingestion/data.zip]
[2025-07-06 14:43:37,743: INFO: data_ingestion: Downloaded data from https://drive.google.com/file/d/1z0mreUtRmR-P-magILsDR3T7M6IkGXtY/view?usp=sharing into file artifacts/data_ingestion/data.zip]
[2025-07-06 14:43:38,232: INFO: main: >>>>>> Stage: Data Ingestion stage completed <<<<<<

x==========x]
[2025-07-06 14:43:38,232: INFO: main: >>>>>> Stage: Prepare base model started <<<<<<]
[2025-07-06 14:43:38,232: INFO: common: yaml file: config\config.yaml loaded successfully]
[2025-07-06 14:43:38,232: INFO: common: yaml file: params.yaml loaded successfully]
[2025-07-06 14:43:38,232: INFO: common: created directory at: artifacts]
[2025-07-06 14:43:38,232: INFO: common: created directory at: artifacts/prepare_base_model]
[2025-07-06 14:43:38,232: ERROR: main: `input_shape` must be a tuple of three integers.]
Traceback (most recent call last):
  File "C:\Users\Ayaz Khan\Desktop\Chest-Cancer-Classification\main.py", line 29, in <module>
    prepare_base_model.main()
  File "C:\Users\Ayaz Khan\Desktop\Chest-Cancer-Classification\src\cnnClassifier\pipeline\stage_02_prepare_base_model.py", line 19, in main
    prepare_base_model.get_base_model()
  File "C:\Users\Ayaz Khan\Desktop\Chest-Cancer-Classification\src\cnnClassifier\components\prepare_base_model.py", line 14, in get_base_model
    self.model = tf.keras.applications.vgg16.VGG16(
                 ^^^^^^^^^^^^^^^^^^^^^^^^^^^^^^^^^^
  File "C:\Users\Ayaz Khan\Desktop\Chest-Cancer-Classification\.venv\Lib\site-packages\keras\src\applications\vgg16.py", line 112, in VGG16
    input_shape = imagenet_utils.obtain_input_shape(
                  ^^^^^^^^^^^^^^^^^^^^^^^^^^^^^^^^^^
  File "C:\Users\Ayaz Khan\Desktop\Chest-Cancer-Classification\.venv\Lib\site-packages\keras\src\applications\imagenet_utils.py", line 379, in obtain_input_shape
    raise ValueError(
ValueError: `input_shape` must be a tuple of three integers.
[2025-07-06 14:45:35,211: INFO: main: >>>>>> Stage: Data Ingestion stage started <<<<<<]
[2025-07-06 14:45:35,211: INFO: common: yaml file: config\config.yaml loaded successfully]
[2025-07-06 14:45:35,211: INFO: common: yaml file: params.yaml loaded successfully]
[2025-07-06 14:45:35,211: INFO: common: created directory at: artifacts]
[2025-07-06 14:45:35,211: INFO: common: created directory at: artifacts/data_ingestion]
[2025-07-06 14:45:35,211: INFO: data_ingestion: Downloading data from https://drive.google.com/file/d/1z0mreUtRmR-P-magILsDR3T7M6IkGXtY/view?usp=sharing into file artifacts/data_ingestion/data.zip]
[2025-07-06 14:46:09,858: INFO: data_ingestion: Downloaded data from https://drive.google.com/file/d/1z0mreUtRmR-P-magILsDR3T7M6IkGXtY/view?usp=sharing into file artifacts/data_ingestion/data.zip]
[2025-07-06 14:46:10,346: INFO: main: >>>>>> Stage: Data Ingestion stage completed <<<<<<

x==========x]
[2025-07-06 14:46:10,346: INFO: main: >>>>>> Stage: Prepare base model started <<<<<<]
[2025-07-06 14:46:10,346: INFO: common: yaml file: config\config.yaml loaded successfully]
[2025-07-06 14:46:10,346: INFO: common: yaml file: params.yaml loaded successfully]
[2025-07-06 14:46:10,346: INFO: common: created directory at: artifacts]
[2025-07-06 14:46:10,346: INFO: common: created directory at: artifacts/prepare_base_model]
[2025-07-06 14:46:34,866: WARNING: saving_api: You are saving your model as an HDF5 file via `model.save()` or `keras.saving.save_model(model)`. This file format is considered legacy. We recommend using instead the native Keras format, e.g. `model.save('my_model.keras')` or `keras.saving.save_model(model, 'my_model.keras')`. ]
[2025-07-06 14:46:35,002: WARNING: saving_api: You are saving your model as an HDF5 file via `model.save()` or `keras.saving.save_model(model)`. This file format is considered legacy. We recommend using instead the native Keras format, e.g. `model.save('my_model.keras')` or `keras.saving.save_model(model, 'my_model.keras')`. ]
[2025-07-06 14:46:35,091: INFO: main: >>>>>> Stage: Prepare base model completed <<<<<<

x==========x]
[2025-07-06 14:46:35,091: INFO: main: >>>>>> Stage: Training started <<<<<<]
[2025-07-06 14:46:35,091: INFO: common: yaml file: config\config.yaml loaded successfully]
[2025-07-06 14:46:35,091: INFO: common: yaml file: params.yaml loaded successfully]
[2025-07-06 14:46:35,091: INFO: common: created directory at: artifacts]
[2025-07-06 14:46:35,091: INFO: common: created directory at: artifacts\training]
[2025-07-06 14:46:35,233: WARNING: saving_utils: Compiled the loaded model, but the compiled metrics have yet to be built. `model.compile_metrics` will be empty until you train or evaluate the model.]
[2025-07-06 14:46:35,320: ERROR: main: tuple index out of range]
Traceback (most recent call last):
  File "C:\Users\Ayaz Khan\Desktop\Chest-Cancer-Classification\main.py", line 40, in <module>
    model_trainer.main()
  File "C:\Users\Ayaz Khan\Desktop\Chest-Cancer-Classification\src\cnnClassifier\pipeline\stage_03_model_trainer.py", line 18, in main
    training.train()
  File "C:\Users\Ayaz Khan\Desktop\Chest-Cancer-Classification\src\cnnClassifier\components\model_trainer.py", line 71, in train
    self.model.fit(
  File "C:\Users\Ayaz Khan\Desktop\Chest-Cancer-Classification\.venv\Lib\site-packages\keras\src\utils\traceback_utils.py", line 122, in error_handler
    raise e.with_traceback(filtered_tb) from None
  File "C:\Users\Ayaz Khan\Desktop\Chest-Cancer-Classification\.venv\Lib\site-packages\keras\src\utils\image_utils.py", line 256, in load_img
    width_height_tuple = (target_size[1], target_size[0])
                          ~~~~~~~~~~~^^^
IndexError: tuple index out of range
[2025-07-06 14:48:01,668: INFO: main: >>>>>> Stage: Data Ingestion stage started <<<<<<]
[2025-07-06 14:48:01,668: INFO: common: yaml file: config\config.yaml loaded successfully]
[2025-07-06 14:48:01,668: INFO: common: yaml file: params.yaml loaded successfully]
[2025-07-06 14:48:01,668: INFO: common: created directory at: artifacts]
[2025-07-06 14:48:01,668: INFO: common: created directory at: artifacts/data_ingestion]
[2025-07-06 14:48:01,668: INFO: data_ingestion: Downloading data from https://drive.google.com/file/d/1z0mreUtRmR-P-magILsDR3T7M6IkGXtY/view?usp=sharing into file artifacts/data_ingestion/data.zip]
[2025-07-06 14:48:19,056: INFO: data_ingestion: Downloaded data from https://drive.google.com/file/d/1z0mreUtRmR-P-magILsDR3T7M6IkGXtY/view?usp=sharing into file artifacts/data_ingestion/data.zip]
[2025-07-06 14:48:19,526: INFO: main: >>>>>> Stage: Data Ingestion stage completed <<<<<<

x==========x]
[2025-07-06 14:48:19,526: INFO: main: >>>>>> Stage: Prepare base model started <<<<<<]
[2025-07-06 14:48:19,526: INFO: common: yaml file: config\config.yaml loaded successfully]
[2025-07-06 14:48:19,526: INFO: common: yaml file: params.yaml loaded successfully]
[2025-07-06 14:48:19,526: INFO: common: created directory at: artifacts]
[2025-07-06 14:48:19,526: INFO: common: created directory at: artifacts/prepare_base_model]
[2025-07-06 14:48:19,845: WARNING: saving_api: You are saving your model as an HDF5 file via `model.save()` or `keras.saving.save_model(model)`. This file format is considered legacy. We recommend using instead the native Keras format, e.g. `model.save('my_model.keras')` or `keras.saving.save_model(model, 'my_model.keras')`. ]
[2025-07-06 14:48:19,986: WARNING: saving_api: You are saving your model as an HDF5 file via `model.save()` or `keras.saving.save_model(model)`. This file format is considered legacy. We recommend using instead the native Keras format, e.g. `model.save('my_model.keras')` or `keras.saving.save_model(model, 'my_model.keras')`. ]
[2025-07-06 14:48:20,067: INFO: main: >>>>>> Stage: Prepare base model completed <<<<<<

x==========x]
[2025-07-06 14:48:20,067: INFO: main: >>>>>> Stage: Training started <<<<<<]
[2025-07-06 14:48:20,068: INFO: common: yaml file: config\config.yaml loaded successfully]
[2025-07-06 14:48:20,068: INFO: common: yaml file: params.yaml loaded successfully]
[2025-07-06 14:48:20,068: INFO: common: created directory at: artifacts]
[2025-07-06 14:48:20,068: INFO: common: created directory at: artifacts\training]
[2025-07-06 14:48:20,203: WARNING: saving_utils: Compiled the loaded model, but the compiled metrics have yet to be built. `model.compile_metrics` will be empty until you train or evaluate the model.]
[2025-07-06 14:48:20,243: ERROR: main: tuple index out of range]
Traceback (most recent call last):
  File "C:\Users\Ayaz Khan\Desktop\Chest-Cancer-Classification\main.py", line 40, in <module>
    model_trainer.main()
  File "C:\Users\Ayaz Khan\Desktop\Chest-Cancer-Classification\src\cnnClassifier\pipeline\stage_03_model_trainer.py", line 18, in main
    training.train()
  File "C:\Users\Ayaz Khan\Desktop\Chest-Cancer-Classification\src\cnnClassifier\components\model_trainer.py", line 71, in train
    self.model.fit(
  File "C:\Users\Ayaz Khan\Desktop\Chest-Cancer-Classification\.venv\Lib\site-packages\keras\src\utils\traceback_utils.py", line 122, in error_handler
    raise e.with_traceback(filtered_tb) from None
  File "C:\Users\Ayaz Khan\Desktop\Chest-Cancer-Classification\.venv\Lib\site-packages\keras\src\utils\image_utils.py", line 256, in load_img
    width_height_tuple = (target_size[1], target_size[0])
                          ~~~~~~~~~~~^^^
IndexError: tuple index out of range
[2025-07-06 14:52:20,594: INFO: main: >>>>>> Stage: Data Ingestion stage started <<<<<<]
[2025-07-06 14:52:20,594: INFO: common: yaml file: config\config.yaml loaded successfully]
[2025-07-06 14:52:20,594: INFO: common: yaml file: params.yaml loaded successfully]
[2025-07-06 14:52:20,594: INFO: common: created directory at: artifacts]
[2025-07-06 14:52:20,594: INFO: common: created directory at: artifacts/data_ingestion]
[2025-07-06 14:52:20,594: INFO: data_ingestion: Downloading data from https://drive.google.com/file/d/1z0mreUtRmR-P-magILsDR3T7M6IkGXtY/view?usp=sharing into file artifacts/data_ingestion/data.zip]
[2025-07-06 14:53:14,902: INFO: data_ingestion: Downloaded data from https://drive.google.com/file/d/1z0mreUtRmR-P-magILsDR3T7M6IkGXtY/view?usp=sharing into file artifacts/data_ingestion/data.zip]
[2025-07-06 14:53:15,384: INFO: main: >>>>>> Stage: Data Ingestion stage completed <<<<<<

x==========x]
[2025-07-06 14:53:15,384: INFO: main: >>>>>> Stage: Prepare base model started <<<<<<]
[2025-07-06 14:53:15,384: INFO: common: yaml file: config\config.yaml loaded successfully]
[2025-07-06 14:53:15,384: INFO: common: yaml file: params.yaml loaded successfully]
[2025-07-06 14:53:15,384: INFO: common: created directory at: artifacts]
[2025-07-06 14:53:15,384: INFO: common: created directory at: artifacts/prepare_base_model]
[2025-07-06 14:53:15,669: WARNING: saving_api: You are saving your model as an HDF5 file via `model.save()` or `keras.saving.save_model(model)`. This file format is considered legacy. We recommend using instead the native Keras format, e.g. `model.save('my_model.keras')` or `keras.saving.save_model(model, 'my_model.keras')`. ]
[2025-07-06 14:53:15,816: WARNING: saving_api: You are saving your model as an HDF5 file via `model.save()` or `keras.saving.save_model(model)`. This file format is considered legacy. We recommend using instead the native Keras format, e.g. `model.save('my_model.keras')` or `keras.saving.save_model(model, 'my_model.keras')`. ]
[2025-07-06 14:53:15,903: INFO: main: >>>>>> Stage: Prepare base model completed <<<<<<

x==========x]
[2025-07-06 14:53:15,903: INFO: main: >>>>>> Stage: Training started <<<<<<]
[2025-07-06 14:53:15,910: INFO: common: yaml file: config\config.yaml loaded successfully]
[2025-07-06 14:53:15,910: INFO: common: yaml file: params.yaml loaded successfully]
[2025-07-06 14:53:15,910: INFO: common: created directory at: artifacts]
[2025-07-06 14:53:15,913: INFO: common: created directory at: artifacts\training]
[2025-07-06 14:53:16,073: WARNING: saving_utils: Compiled the loaded model, but the compiled metrics have yet to be built. `model.compile_metrics` will be empty until you train or evaluate the model.]
[2025-07-06 14:53:17,737: ERROR: main: numpy() is only available when eager execution is enabled.]
Traceback (most recent call last):
  File "C:\Users\Ayaz Khan\Desktop\Chest-Cancer-Classification\main.py", line 40, in <module>
    model_trainer.main()
  File "C:\Users\Ayaz Khan\Desktop\Chest-Cancer-Classification\src\cnnClassifier\pipeline\stage_03_model_trainer.py", line 18, in main
    training.train()
  File "C:\Users\Ayaz Khan\Desktop\Chest-Cancer-Classification\src\cnnClassifier\components\model_trainer.py", line 70, in train
    self.model.fit(
  File "C:\Users\Ayaz Khan\Desktop\Chest-Cancer-Classification\.venv\Lib\site-packages\keras\src\utils\traceback_utils.py", line 122, in error_handler
    raise e.with_traceback(filtered_tb) from None
  File "C:\Users\Ayaz Khan\Desktop\Chest-Cancer-Classification\.venv\Lib\site-packages\keras\src\backend\tensorflow\core.py", line 171, in convert_to_numpy
    return np.array(x)
           ^^^^^^^^^^^
NotImplementedError: numpy() is only available when eager execution is enabled.
[2025-07-06 14:58:47,294: INFO: main: >>>>>> Stage: Data Ingestion stage started <<<<<<]
[2025-07-06 14:58:47,294: INFO: common: yaml file: config\config.yaml loaded successfully]
[2025-07-06 14:58:47,294: INFO: common: yaml file: params.yaml loaded successfully]
[2025-07-06 14:58:47,307: INFO: common: created directory at: artifacts]
[2025-07-06 14:58:47,307: INFO: common: created directory at: artifacts/data_ingestion]
[2025-07-06 14:58:47,307: INFO: data_ingestion: Downloading data from https://drive.google.com/file/d/1z0mreUtRmR-P-magILsDR3T7M6IkGXtY/view?usp=sharing into file artifacts/data_ingestion/data.zip]
[2025-07-06 14:59:42,580: INFO: data_ingestion: Downloaded data from https://drive.google.com/file/d/1z0mreUtRmR-P-magILsDR3T7M6IkGXtY/view?usp=sharing into file artifacts/data_ingestion/data.zip]
[2025-07-06 14:59:43,045: INFO: main: >>>>>> Stage: Data Ingestion stage completed <<<<<<

x==========x]
[2025-07-06 14:59:43,045: INFO: main: >>>>>> Stage: Prepare base model started <<<<<<]
[2025-07-06 14:59:43,046: INFO: common: yaml file: config\config.yaml loaded successfully]
[2025-07-06 14:59:43,046: INFO: common: yaml file: params.yaml loaded successfully]
[2025-07-06 14:59:43,046: INFO: common: created directory at: artifacts]
[2025-07-06 14:59:43,046: INFO: common: created directory at: artifacts/prepare_base_model]
[2025-07-06 14:59:43,373: WARNING: saving_api: You are saving your model as an HDF5 file via `model.save()` or `keras.saving.save_model(model)`. This file format is considered legacy. We recommend using instead the native Keras format, e.g. `model.save('my_model.keras')` or `keras.saving.save_model(model, 'my_model.keras')`. ]
[2025-07-06 14:59:43,515: WARNING: saving_api: You are saving your model as an HDF5 file via `model.save()` or `keras.saving.save_model(model)`. This file format is considered legacy. We recommend using instead the native Keras format, e.g. `model.save('my_model.keras')` or `keras.saving.save_model(model, 'my_model.keras')`. ]
[2025-07-06 14:59:43,610: INFO: main: >>>>>> Stage: Prepare base model completed <<<<<<

x==========x]
[2025-07-06 14:59:43,610: INFO: main: >>>>>> Stage: Training started <<<<<<]
[2025-07-06 14:59:43,610: INFO: common: yaml file: config\config.yaml loaded successfully]
[2025-07-06 14:59:43,610: INFO: common: yaml file: params.yaml loaded successfully]
[2025-07-06 14:59:43,610: INFO: common: created directory at: artifacts]
[2025-07-06 14:59:43,610: INFO: common: created directory at: artifacts\training]
[2025-07-06 14:59:43,751: WARNING: saving_utils: Compiled the loaded model, but the compiled metrics have yet to be built. `model.compile_metrics` will be empty until you train or evaluate the model.]
[2025-07-06 14:59:45,326: ERROR: main: numpy() is only available when eager execution is enabled.]
Traceback (most recent call last):
  File "C:\Users\Ayaz Khan\Desktop\Chest-Cancer-Classification\main.py", line 40, in <module>
    model_trainer.main()
  File "C:\Users\Ayaz Khan\Desktop\Chest-Cancer-Classification\src\cnnClassifier\pipeline\stage_03_model_trainer.py", line 18, in main
    training.train()
  File "C:\Users\Ayaz Khan\Desktop\Chest-Cancer-Classification\src\cnnClassifier\components\model_trainer.py", line 70, in train
    self.model.fit(
  File "C:\Users\Ayaz Khan\Desktop\Chest-Cancer-Classification\.venv\Lib\site-packages\keras\src\utils\traceback_utils.py", line 122, in error_handler
    raise e.with_traceback(filtered_tb) from None
  File "C:\Users\Ayaz Khan\Desktop\Chest-Cancer-Classification\.venv\Lib\site-packages\keras\src\backend\tensorflow\core.py", line 171, in convert_to_numpy
    return np.array(x)
           ^^^^^^^^^^^
NotImplementedError: numpy() is only available when eager execution is enabled.
[2025-07-06 15:21:12,964: INFO: common: yaml file: config\config.yaml loaded successfully]
[2025-07-06 15:21:12,967: INFO: common: yaml file: params.yaml loaded successfully]
[2025-07-06 15:21:12,970: INFO: common: created directory at: artifacts]
[2025-07-06 15:21:12,973: INFO: common: created directory at: artifacts/data_ingestion]
[2025-07-06 15:21:12,973: INFO: 1533896105: Downloading data from https://drive.google.com/file/d/1z0mreUtRmR-P-magILsDR3T7M6IkGXtY/view?usp=sharing into file artifacts/data_ingestion/data.zip]
[2025-07-06 15:22:23,169: INFO: 1533896105: Downloaded data from https://drive.google.com/file/d/1z0mreUtRmR-P-magILsDR3T7M6IkGXtY/view?usp=sharing into file artifacts/data_ingestion/data.zip]
[2025-07-08 00:38:51,830: INFO: common: yaml file: config\config.yaml loaded successfully]
[2025-07-08 00:38:51,854: INFO: common: yaml file: params.yaml loaded successfully]
[2025-07-08 00:38:51,854: INFO: common: created directory at: artifacts]
[2025-07-08 00:38:51,854: INFO: common: created directory at: artifacts/prepare_base_model]
[2025-07-08 00:39:39,480: INFO: common: yaml file: config\config.yaml loaded successfully]
[2025-07-08 00:39:39,496: INFO: common: yaml file: params.yaml loaded successfully]
[2025-07-08 00:39:39,496: INFO: common: created directory at: artifacts]
[2025-07-08 00:39:39,496: INFO: common: created directory at: artifacts/prepare_base_model]
[2025-07-08 00:40:33,785: INFO: common: yaml file: config\config.yaml loaded successfully]
[2025-07-08 00:40:33,787: INFO: common: yaml file: params.yaml loaded successfully]
[2025-07-08 00:40:33,787: INFO: common: created directory at: artifacts]
[2025-07-08 00:40:33,787: INFO: common: created directory at: artifacts/prepare_base_model]
[2025-07-08 00:41:40,423: INFO: common: yaml file: config\config.yaml loaded successfully]
[2025-07-08 00:41:40,427: INFO: common: yaml file: params.yaml loaded successfully]
[2025-07-08 00:41:40,429: INFO: common: created directory at: artifacts]
[2025-07-08 00:41:40,430: INFO: common: created directory at: artifacts/prepare_base_model]
[2025-07-08 00:52:06,393: INFO: 2544626313: >>>>>> Prepare Base Model Stage started <<<<<<]
[2025-07-08 00:52:06,398: INFO: common: yaml file: config\config.yaml loaded successfully]
[2025-07-08 00:52:06,401: INFO: common: yaml file: params.yaml loaded successfully]
[2025-07-08 00:52:06,403: INFO: common: created directory at: artifacts]
[2025-07-08 00:52:06,403: INFO: common: created directory at: artifacts/prepare_base_model]
[2025-07-08 00:52:06,403: ERROR: 2544626313: Exception occurred in Prepare Base Model Stage: `input_shape` must be a tuple of three integers.]
Traceback (most recent call last):
  File "C:\Users\Ayaz Khan\AppData\Local\Temp\ipykernel_12136\2544626313.py", line 14, in <module>
    prepare_base_model.get_base_model()
  File "C:\Users\Ayaz Khan\Desktop\Chest-Cancer-Classification\src\cnnClassifier\components\prepare_base_model.py", line 14, in get_base_model
    self.model = tf.keras.applications.vgg16.VGG16(
                 ^^^^^^^^^^^^^^^^^^^^^^^^^^^^^^^^^^
  File "C:\Users\Ayaz Khan\Desktop\Chest-Cancer-Classification\.venv\Lib\site-packages\keras\src\applications\vgg16.py", line 112, in VGG16
    input_shape = imagenet_utils.obtain_input_shape(
                  ^^^^^^^^^^^^^^^^^^^^^^^^^^^^^^^^^^
  File "C:\Users\Ayaz Khan\Desktop\Chest-Cancer-Classification\.venv\Lib\site-packages\keras\src\applications\imagenet_utils.py", line 379, in obtain_input_shape
    raise ValueError(
ValueError: `input_shape` must be a tuple of three integers.
[2025-07-08 00:56:09,037: INFO: 3430649218: >>>>>> Prepare Base Model Stage started <<<<<<]
[2025-07-08 00:56:09,037: INFO: common: yaml file: config\config.yaml loaded successfully]
[2025-07-08 00:56:09,055: INFO: common: yaml file: params.yaml loaded successfully]
[2025-07-08 00:56:09,055: INFO: common: created directory at: artifacts]
[2025-07-08 00:56:09,055: INFO: common: created directory at: artifacts/prepare_base_model]
[2025-07-08 00:56:09,055: ERROR: 3430649218: Exception occurred in Prepare Base Model Stage: `input_shape` must be a tuple of three integers.]
Traceback (most recent call last):
  File "C:\Users\Ayaz Khan\AppData\Local\Temp\ipykernel_12136\3430649218.py", line 14, in <module>
    prepare_base_model.get_base_model()
  File "C:\Users\Ayaz Khan\Desktop\Chest-Cancer-Classification\src\cnnClassifier\components\prepare_base_model.py", line 14, in get_base_model
    self.model = tf.keras.applications.vgg16.VGG16(
                 ^^^^^^^^^^^^^^^^^^^^^^^^^^^^^^^^^^
  File "C:\Users\Ayaz Khan\Desktop\Chest-Cancer-Classification\.venv\Lib\site-packages\keras\src\applications\vgg16.py", line 112, in VGG16
    input_shape = imagenet_utils.obtain_input_shape(
                  ^^^^^^^^^^^^^^^^^^^^^^^^^^^^^^^^^^
  File "C:\Users\Ayaz Khan\Desktop\Chest-Cancer-Classification\.venv\Lib\site-packages\keras\src\applications\imagenet_utils.py", line 379, in obtain_input_shape
    raise ValueError(
ValueError: `input_shape` must be a tuple of three integers.
[2025-07-08 01:09:09,460: INFO: common: yaml file: config\config.yaml loaded successfully]
[2025-07-08 01:09:09,465: INFO: common: yaml file: params.yaml loaded successfully]
[2025-07-08 01:09:09,468: INFO: common: created directory at: artifacts]
[2025-07-08 01:09:09,475: INFO: common: created directory at: artifacts/prepare_base_model]
[2025-07-08 01:09:10,487: WARNING: saving_api: You are saving your model as an HDF5 file via `model.save()` or `keras.saving.save_model(model)`. This file format is considered legacy. We recommend using instead the native Keras format, e.g. `model.save('my_model.keras')` or `keras.saving.save_model(model, 'my_model.keras')`. ]
[2025-07-08 01:09:10,741: WARNING: saving_api: You are saving your model as an HDF5 file via `model.save()` or `keras.saving.save_model(model)`. This file format is considered legacy. We recommend using instead the native Keras format, e.g. `model.save('my_model.keras')` or `keras.saving.save_model(model, 'my_model.keras')`. ]
[2025-07-08 01:16:42,229: INFO: common: yaml file: config\config.yaml loaded successfully]
[2025-07-08 01:16:42,235: INFO: common: yaml file: params.yaml loaded successfully]
[2025-07-08 01:16:42,240: INFO: common: created directory at: artifacts]
[2025-07-08 01:16:42,243: INFO: common: created directory at: artifacts\training]
[2025-07-08 01:16:42,662: WARNING: saving_utils: Compiled the loaded model, but the compiled metrics have yet to be built. `model.compile_metrics` will be empty until you train or evaluate the model.]
[2025-07-08 01:17:13,807: INFO: common: yaml file: config\config.yaml loaded successfully]
[2025-07-08 01:17:13,809: INFO: common: yaml file: params.yaml loaded successfully]
[2025-07-08 01:17:13,811: INFO: common: created directory at: artifacts]
[2025-07-08 01:17:13,812: INFO: common: created directory at: artifacts\training]
[2025-07-08 01:17:13,956: WARNING: saving_utils: Compiled the loaded model, but the compiled metrics have yet to be built. `model.compile_metrics` will be empty until you train or evaluate the model.]
[2025-07-08 01:21:17,994: INFO: common: yaml file: config\config.yaml loaded successfully]
[2025-07-08 01:21:17,998: INFO: common: yaml file: params.yaml loaded successfully]
[2025-07-08 01:21:17,999: INFO: common: created directory at: artifacts]
[2025-07-08 01:21:18,001: INFO: common: created directory at: artifacts\training]
[2025-07-08 01:21:18,143: WARNING: saving_utils: Compiled the loaded model, but the compiled metrics have yet to be built. `model.compile_metrics` will be empty until you train or evaluate the model.]
[2025-07-08 01:23:01,310: INFO: common: yaml file: config\config.yaml loaded successfully]
[2025-07-08 01:23:01,313: INFO: common: yaml file: params.yaml loaded successfully]
[2025-07-08 01:23:01,314: INFO: common: created directory at: artifacts]
[2025-07-08 01:23:01,315: INFO: common: created directory at: artifacts\training]
[2025-07-08 01:23:01,459: WARNING: saving_utils: Compiled the loaded model, but the compiled metrics have yet to be built. `model.compile_metrics` will be empty until you train or evaluate the model.]
[2025-07-08 01:24:18,205: INFO: common: yaml file: config\config.yaml loaded successfully]
[2025-07-08 01:24:18,209: INFO: common: yaml file: params.yaml loaded successfully]
[2025-07-08 01:24:18,211: INFO: common: created directory at: artifacts]
[2025-07-08 01:24:18,212: INFO: common: created directory at: artifacts\training]
[2025-07-08 01:24:18,353: WARNING: saving_utils: Compiled the loaded model, but the compiled metrics have yet to be built. `model.compile_metrics` will be empty until you train or evaluate the model.]
[2025-07-08 01:24:33,114: INFO: common: yaml file: config\config.yaml loaded successfully]
[2025-07-08 01:24:33,118: INFO: common: yaml file: params.yaml loaded successfully]
[2025-07-08 01:24:33,120: INFO: common: created directory at: artifacts]
[2025-07-08 01:24:33,122: INFO: common: created directory at: artifacts\training]
[2025-07-08 01:24:33,268: WARNING: saving_utils: Compiled the loaded model, but the compiled metrics have yet to be built. `model.compile_metrics` will be empty until you train or evaluate the model.]
[2025-07-08 01:25:13,239: INFO: common: yaml file: config\config.yaml loaded successfully]
[2025-07-08 01:25:13,241: INFO: common: yaml file: params.yaml loaded successfully]
[2025-07-08 01:25:13,243: INFO: common: created directory at: artifacts]
[2025-07-08 01:25:13,244: INFO: common: created directory at: artifacts\training]
[2025-07-08 01:25:13,580: WARNING: saving_utils: Compiled the loaded model, but the compiled metrics have yet to be built. `model.compile_metrics` will be empty until you train or evaluate the model.]
[2025-07-08 01:25:52,833: INFO: common: yaml file: config\config.yaml loaded successfully]
[2025-07-08 01:25:52,834: INFO: common: yaml file: params.yaml loaded successfully]
[2025-07-08 01:25:52,836: INFO: common: created directory at: artifacts]
[2025-07-08 01:25:52,837: INFO: common: created directory at: artifacts\training]
[2025-07-08 01:25:53,090: WARNING: saving_utils: Compiled the loaded model, but the compiled metrics have yet to be built. `model.compile_metrics` will be empty until you train or evaluate the model.]
[2025-07-08 01:26:13,279: INFO: common: yaml file: config\config.yaml loaded successfully]
[2025-07-08 01:26:13,283: INFO: common: yaml file: params.yaml loaded successfully]
[2025-07-08 01:26:13,286: INFO: common: created directory at: artifacts]
[2025-07-08 01:26:13,290: INFO: common: created directory at: artifacts\training]
[2025-07-08 01:26:15,323: WARNING: saving_utils: Compiled the loaded model, but the compiled metrics have yet to be built. `model.compile_metrics` will be empty until you train or evaluate the model.]
[2025-07-08 01:34:59,953: INFO: common: yaml file: config\config.yaml loaded successfully]
[2025-07-08 01:34:59,955: INFO: common: yaml file: params.yaml loaded successfully]
[2025-07-08 01:34:59,956: INFO: common: created directory at: artifacts]
[2025-07-08 01:34:59,958: INFO: common: created directory at: artifacts\training]
[2025-07-08 01:35:00,089: WARNING: saving_utils: Compiled the loaded model, but the compiled metrics have yet to be built. `model.compile_metrics` will be empty until you train or evaluate the model.]
[2025-07-09 00:04:45,004: INFO: common: yaml file: config\config.yaml loaded successfully]
[2025-07-09 00:04:45,009: INFO: common: yaml file: params.yaml loaded successfully]
[2025-07-09 00:04:45,012: INFO: common: created directory at: artifacts]
[2025-07-09 00:04:46,056: INFO: common: yaml file: config\config.yaml loaded successfully]
[2025-07-09 00:04:46,058: INFO: common: yaml file: params.yaml loaded successfully]
[2025-07-09 00:04:46,059: INFO: common: created directory at: artifacts]
[2025-07-09 00:04:46,061: INFO: common: created directory at: artifacts\training]
[2025-07-09 00:04:48,615: INFO: common: yaml file: config\config.yaml loaded successfully]
[2025-07-09 00:04:48,619: INFO: common: yaml file: params.yaml loaded successfully]
[2025-07-09 00:04:48,621: INFO: common: created directory at: artifacts]
[2025-07-09 00:04:48,623: INFO: common: created directory at: artifacts\training]
[2025-07-09 00:04:48,894: WARNING: saving_utils: Compiled the loaded model, but the compiled metrics have yet to be built. `model.compile_metrics` will be empty until you train or evaluate the model.]
[2025-07-09 00:14:10,993: WARNING: saving_api: You are saving your model as an HDF5 file via `model.save()` or `keras.saving.save_model(model)`. This file format is considered legacy. We recommend using instead the native Keras format, e.g. `model.save('my_model.keras')` or `keras.saving.save_model(model, 'my_model.keras')`. ]
